Workbook

Sheet Инструкции
B2: Рецептурник и себестойност — как се ползва
B5: Този файл е шаблон. Съдържа примерни турски ястия за Бяла къща (Балчик) — заменете ги с реалните рецепти и текущите доставни цени на съставките.
B7: Цветен код:
B8: • Жълто/синьо = клетки за въвеждане (тук пишеш ти или собственикът)
B9: • Черно = формула — смята се автоматично, не се пипа на ръка
B11: Листове, по ред:
B12: 1. Съставки — списък на всички съставки, цена за единица и алергени. Тръгва оттук — първо въведи актуалните доставни цени.
B13: 2. Кухненска_карта — за всяко ястие: съставки, количества и начин на приготвяне. Себестойността се смята автоматично при промяна на количество или цена в 'Съставки'.
B14: 3. Рецепти — обобщена картина за всяко ястие: себестойност/порция, алергени (автоматично изведени от съставките), описание за менюто.
B15: 4. Ценообразуване — задай целеви food cost % (горе вляво) — получаваш предложена продажна цена. Въведи и актуалната цена от менюто, за да видиш реалния % и дали е над таргета.
B16: 5. Меню — клиентска версия за печат, групирана по категории, без себестойност.
B18: Как да добавиш ново ястие:
... B25: Алергенната информация следва Регламент (ЕС) № 1169/2011, Приложение II (14-те основни алергена). Проверявай я — автоматичното извеждане е само толкова точно, колкото маркировките, въведени в 'Съставки'.

Sheet Съставки
A1: Име на съставка | B1: Мерна единица | C1: Цена/единица (лв) | D1: Доставчик | E1: Глутен | F1: Ракообразни | G1: Яйца | H1: Риба | I1: Фъстъци | J1: Соя | K1: Мляко | L1: Ядки | M1: Целина | N1: Синап | O1: Сусам | P1: Серен диоксид/сулфити | Q1: Лупина | R1: Мекотели
A2: Агнешко месо | B2: кг | C2: 24 | D2: Месокомбинат Балчик | E2: 0 | F2: 0 | G2: 0 | H2: 0 | I2: 0 | J2: 0 | K2: 0 | L2: 0 | M2: 0 | N2: 0 | O2: 0 | P2: 0 | Q2: 0 | R2: 0
A3: Телешко месо кайма | B3: кг | C3: 18 | D3: Месокомбинат Балчик | E3: 0 | F3: 0 | G3: 0 | H3: 0 | I3: 0 | J3: 0 | K3: 0 | L3: 0 | M3: 0 | N3: 0 | O3: 0 | P3: 0 | Q3: 0 | R3: 0
A4: Телешко месо (филе за дюнер) | B4: кг | C4: 26 | D4: Месокомбинат Балчик | E4: 0 | F4: 0 | G4: 0 | H4: 0 | I4: 0 | J4: 0 | K4: 0 | L4: 0 | M4: 0 | N4: 0 | O4: 0 | P4: 0 | Q4: 0 | R4: 0
A5: Пилешко филе | B5: кг | C5: 12 | D5: Месокомбинат Балчик | E5: 0 | F5: 0 | G5: 0 | H5: 0 | I5: 0 | J5: 0 | K5: 0 | L5: 0 | M5: 0 | N5: 0 | O5: 0 | P5: 0 | Q5: 0 | R5: 0
A6: Кисело мляко | B6: кг | C6: 4.5 | D6: Мандра Добрич | E6: 0 | F6: 0 | G6: 0 | H6: 0 | I6: 0 | J6: 0 | K6: 1 | L6: 0 | M6: 0 | N6: 0 | O6: 0 | P6: 0 | Q6: 0 | R6: 0
A7: Домати | B7: кг | C7: 3.2 | D7: Зеленчуци Балчик | E7: 0 | F7: 0 | G7: 0 | H7: 0 | I7: 0 | J7: 0 | K7: 0 | L7: 0 | M7: 0 | N7: 0 | O7: 0 | P7: 0 | Q7: 0 | R7: 0
A8: Краставици | B8: кг | C8: 2.8 | D8: Зеленчуци Балчик | E8: 0 | F8: 0 | G8: 0 | H8: 0 | I8: 0 | J8: 0 | K8: 0 | L8: 0 | M8: 0 | N8: 0 | O8: 0 | P8: 0 | Q8: 0 | R8: 0
A9: Червен лук | B9: кг | C9: 2 | D9: Зеленчуци Балчик | E9: 0 | F9: 0 | G9: 0 | H9: 0 | I9: 0 | J9: 0 | K9: 0 | L9: 0 | M9: 0 | N9: 0 | O9: 0 | P9: 0 | Q9: 0 | R9: 0
A10: Чесън | B10: кг | C10: 8 | D10: Зеленчуци Балчик | E10: 0 | F10: 0 | G10: 0 | H10: 0 | I10: 0 | J10: 0 | K10: 0 | L10: 0 | M10: 0 | N10: 0 | O10: 0 | P10: 0 | Q10: 0 | R10: 0
A11: Червена леща | B11: кг | C11: 4.2 | D11: Метро | E11: 0 | F11: 0 | G11: 0 | H11: 0 | I11: 0 | J11: 0 | K11: 0 | L11: 0 | M11: 0 | N11: 0 | O11: 0 | P11: 0 | Q11: 0 | R11: 0
A12: Булгур | B12: кг | C12: 3.5 | D12: Метро | E12: 1 | F12: 0 | G12: 0 | H12: 0 | I12: 0 | J12: 0 | K12: 0 | L12: 0 | M12: 0 | N12: 0 | O12: 0 | P12: 0 | Q12: 0 | R12: 0
A13: Домат паста | B13: кг | C13: 6 | D13: Метро | E13: 0 | F13: 0 | G13: 0 | H13: 0 | I13: 0 | J13: 0 | K13: 0 | L13: 0 | M13: 0 | N13: 0 | O13: 0 | P13: 0 | Q13: 0 | R13: 0
... A34: Маслини | B34: кг | C34: 9 | D34: Метро | E34: 0 | F34: 0 | G34: 0 | H34: 0 | I34: 0 | J34: 0 | K34: 0 | L34: 0 | M34: 0 | N34: 0 | O34: 0 | P34: 0 | Q34: 0 | R34: 0
A36: Забележка: 1 = съдържа алергена, 0 = не съдържа. Колона C (жълто) е единственото, което трябва да обновяваш при промяна на доставна цена.

Sheet Кухненска_карта
A2: Чорба Езогелин / Ezogelin Soup
A3: Категория: | B3: Предястия | C3: Порции: | D3: =INDEX('Рецепти'!$E:$E,2) | E3: Себестойност/порция: | F3: =INDEX('Рецепти'!$G:$G,2)
A4: Приготвяне: Задушете лука в маслото, добавете доматената паста, лещата и булгура. Залейте с вода и варете на слаб огън 25 мин. Овкусете с червен пипер и сол.
A5: Ястие (за справка) | B5: Съставка | C5: Количество | D5: Мярка | E5: Цена/ед. (лв) | F5: Стойност (лв)
A6: Чорба Езогелин | B6: Червена леща | C6: 0.4 | D6: =IF($B6="","",INDEX('Съставки'!$B$2:$B$34,MATCH($B6,'Съставки'!$A$2:$A$34,0))) | E6: =IF($B6="","",INDEX('Съставки'!$C$2:$C$34,MATCH($B6,'Съставки'!$A$2:$A$34,0))) | F6: =IF($B6="","",$C6*$E6) | G6: =IF($B6="",0,INDEX('Съставки'!$E$2:$E$34,MATCH($B6,'Съставки'!$A$2:$A$34,0))) | H6: =IF($B6="",0,INDEX('Съставки'!$F$2:$F$34,MATCH($B6,'Съставки'!$A$2:$A$34,0))) | I6: =IF($B6="",0,INDEX('Съставки'!$G$2:$G$34,MATCH($B6,'Съставки'!$A$2:$A$34,0))) | J6: =IF($B6="",0,INDEX('Съставки'!$H$2:$H$34,MATCH($B6,'Съставки'!$A$2:$A$34,0))) | K6: =IF($B6="",0,INDEX('Съставки'!$I$2:$I$34,MATCH($B6,'Съставки'!$A$2:$A$34,0))) | L6: =IF($B6="",0,INDEX('Съставки'!$J$2:$J$34,MATCH($B6,'Съставки'!$A$2:$A$34,0))) | M6: =IF($B6="",0,INDEX('Съставки'!$K$2:$K$34,MATCH($B6,'Съставки'!$A$2:$A$34,0))) | N6: =IF($B6="",0,INDEX('Съставки'!$L$2:$L$34,MATCH($B6,'Съставки'!$A$2:$A$34,0))) | O6: =IF($B6="",0,INDEX('Съставки'!$M$2:$M$34,MATCH($B6,'Съставки'!$A$2:$A$34,0))) | P6: =IF($B6="",0,INDEX('Съставки'!$N$2:$N$34,MATCH($B6,'Съставки'!$A$2:$A$34,0))) | Q6: =IF($B6="",0,INDEX('Съставки'!$O$2:$O$34,MATCH($B6,'Съставки'!$A$2:$A$34,0))) | R6: =IF($B6="",0,INDEX('Съставки'!$P$2:$P$34,MATCH($B6,'Съставки'!$A$2:$A$34,0))) | S6: =IF($B6="",0,INDEX('Съставки'!$Q$2:$Q$34,MATCH($B6,'Съставки'!$A$2:$A$34,0))) | T6: =IF($B6="",0,INDEX('Съставки'!$R$2:$R$34,MATCH($B6,'Съставки'!$A$2:$A$34,0)))
A7: Чорба Езогелин | B7: Булгур | C7: 0.1 | D7: =IF($B7="","",INDEX('Съставки'!$B$2:$B$34,MATCH($B7,'Съставки'!$A$2:$A$34,0))) | E7: =IF($B7="","",INDEX('Съставки'!$C$2:$C$34,MATCH($B7,'Съставки'!$A$2:$A$34,0))) | F7: =IF($B7="","",$C7*$E7) | G7: =IF($B7="",0,INDEX('Съставки'!$E$2:$E$34,MATCH($B7,'Съставки'!$A$2:$A$34,0))) | H7: =IF($B7="",0,INDEX('Съставки'!$F$2:$F$34,MATCH($B7,'Съставки'!$A$2:$A$34,0))) | I7: =IF($B7="",0,INDEX('Съставки'!$G$2:$G$34,MATCH($B7,'Съставки'!$A$2:$A$34,0))) | J7: =IF($B7="",0,INDEX('Съставки'!$H$2:$H$34,MATCH($B7,'Съставки'!$A$2:$A$34,0))) | K7: =IF($B7="",0,INDEX('Съставки'!$I$2:$I$34,MATCH($B7,'Съставки'!$A$2:$A$34,0))) | L7: =IF($B7="",0,INDEX('Съставки'!$J$2:$J$34,MATCH($B7,'Съставки'!$A$2:$A$34,0))) | M7: =IF($B7="",0,INDEX('Съставки'!$K$2:$K$34,MATCH($B7,'Съставки'!$A$2:$A$34,0))) | N7: =IF($B7="",0,INDEX('Съставки'!$L$2:$L$34,MATCH($B7,'Съставки'!$A$2:$A$34,0))) | O7: =IF($B7="",0,INDEX('Съставки'!$M$2:$M$34,MATCH($B7,'Съставки'!$A$2:$A$34,0))) | P7: =IF($B7="",0,INDEX('Съставки'!$N$2:$N$34,MATCH($B7,'Съставки'!$A$2:$A$34,0))) | Q7: =IF($B7="",0,INDEX('Съставки'!$O$2:$O$34,MATCH($B7,'Съставки'!$A$2:$A$34,0))) | R7: =IF($B7="",0,INDEX('Съставки'!$P$2:$P$34,MATCH($B7,'Съставки'!$A$2:$A$34,0))) | S7: =IF($B7="",0,INDEX('Съставки'!$Q$2:$Q$34,MATCH($B7,'Съставки'!$A$2:$A$34,0))) | T7: =IF($B7="",0,INDEX('Съставки'!$R$2:$R$34,MATCH($B7,'Съставки'!$A$2:$A$34,0)))
A8: Чорба Езогелин | B8: Червен лук | C8: 0.15 | D8: =IF($B8="","",INDEX('Съставки'!$B$2:$B$34,MATCH($B8,'Съставки'!$A$2:$A$34,0))) | E8: =IF($B8="","",INDEX('Съставки'!$C$2:$C$34,MATCH($B8,'Съставки'!$A$2:$A$34,0))) | F8: =IF($B8="","",$C8*$E8) | G8: =IF($B8="",0,INDEX('Съставки'!$E$2:$E$34,MATCH($B8,'Съставки'!$A$2:$A$34,0))) | H8: =IF($B8="",0,INDEX('Съставки'!$F$2:$F$34,MATCH($B8,'Съставки'!$A$2:$A$34,0))) | I8: =IF($B8="",0,INDEX('Съставки'!$G$2:$G$34,MATCH($B8,'Съставки'!$A$2:$A$34,0))) | J8: =IF($B8="",0,INDEX('Съставки'!$H$2:$H$34,MATCH($B8,'Съставки'!$A$2:$A$34,0))) | K8: =IF($B8="",0,INDEX('Съставки'!$I$2:$I$34,MATCH($B8,'Съставки'!$A$2:$A$34,0))) | L8: =IF($B8="",0,INDEX('Съставки'!$J$2:$J$34,MATCH($B8,'Съставки'!$A$2:$A$34,0))) | M8: =IF($B8="",0,INDEX('Съставки'!$K$2:$K$34,MATCH($B8,'Съставки'!$A$2:$A$34,0))) | N8: =IF($B8="",0,INDEX('Съставки'!$L$2:$L$34,MATCH($B8,'Съставки'!$A$2:$A$34,0))) | O8: =IF($B8="",0,INDEX('Съставки'!$M$2:$M$34,MATCH($B8,'Съставки'!$A$2:$A$34,0))) | P8: =IF($B8="",0,INDEX('Съставки'!$N$2:$N$34,MATCH($B8,'Съставки'!$A$2:$A$34,0))) | Q8: =IF($B8="",0,INDEX('Съставки'!$O$2:$O$34,MATCH($B8,'Съставки'!$A$2:$A$34,0))) | R8: =IF($B8="",0,INDEX('Съставки'!$P$2:$P$34,MATCH($B8,'Съставки'!$A$2:$A$34,0))) | S8: =IF($B8="",0,INDEX('Съставки'!$Q$2:$Q$34,MATCH($B8,'Съставки'!$A$2:$A$34,0))) | T8: =IF($B8="",0,INDEX('Съставки'!$R$2:$R$34,MATCH($B8,'Съставки'!$A$2:$A$34,0)))
A9: Чорба Езогелин | B9: Домат паста | C9: 0.08 | D9: =IF($B9="","",INDEX('Съставки'!$B$2:$B$34,MATCH($B9,'Съставки'!$A$2:$A$34,0))) | E9: =IF($B9="","",INDEX('Съставки'!$C$2:$C$34,MATCH($B9,'Съставки'!$A$2:$A$34,0))) | F9: =IF($B9="","",$C9*$E9) | G9: =IF($B9="",0,INDEX('Съставки'!$E$2:$E$34,MATCH($B9,'Съставки'!$A$2:$A$34,0))) | H9: =IF($B9="",0,INDEX('Съставки'!$F$2:$F$34,MATCH($B9,'Съставки'!$A$2:$A$34,0))) | I9: =IF($B9="",0,INDEX('Съставки'!$G$2:$G$34,MATCH($B9,'Съставки'!$A$2:$A$34,0))) | J9: =IF($B9="",0,INDEX('Съставки'!$H$2:$H$34,MATCH($B9,'Съставки'!$A$2:$A$34,0))) | K9: =IF($B9="",0,INDEX('Съставки'!$I$2:$I$34,MATCH($B9,'Съставки'!$A$2:$A$34,0))) | L9: =IF($B9="",0,INDEX('Съставки'!$J$2:$J$34,MATCH($B9,'Съставки'!$A$2:$A$34,0))) | M9: =IF($B9="",0,INDEX('Съставки'!$K$2:$K$34,MATCH($B9,'Съставки'!$A$2:$A$34,0))) | N9: =IF($B9="",0,INDEX('Съставки'!$L$2:$L$34,MATCH($B9,'Съставки'!$A$2:$A$34,0))) | O9: =IF($B9="",0,INDEX('Съставки'!$M$2:$M$34,MATCH($B9,'Съставки'!$A$2:$A$34,0))) | P9: =IF($B9="",0,INDEX('Съставки'!$N$2:$N$34,MATCH($B9,'Съставки'!$A$2:$A$34,0))) | Q9: =IF($B9="",0,INDEX('Съставки'!$O$2:$O$34,MATCH($B9,'Съставки'!$A$2:$A$34,0))) | R9: =IF($B9="",0,INDEX('Съставки'!$P$2:$P$34,MATCH($B9,'Съставки'!$A$2:$A$34,0))) | S9: =IF($B9="",0,INDEX('Съставки'!$Q$2:$Q$34,MATCH($B9,'Съставки'!$A$2:$A$34,0))) | T9: =IF($B9="",0,INDEX('Съставки'!$R$2:$R$34,MATCH($B9,'Съставки'!$A$2:$A$34,0)))
A10: Чорба Езогелин | B10: Масло | C10: 0.06 | D10: =IF($B10="","",INDEX('Съставки'!$B$2:$B$34,MATCH($B10,'Съставки'!$A$2:$A$34,0))) | E10: =IF($B10="","",INDEX('Съставки'!$C$2:$C$34,MATCH($B10,'Съставки'!$A$2:$A$34,0))) | F10: =IF($B10="","",$C10*$E10) | G10: =IF($B10="",0,INDEX('Съставки'!$E$2:$E$34,MATCH($B10,'Съставки'!$A$2:$A$34,0))) | H10: =IF($B10="",0,INDEX('Съставки'!$F$2:$F$34,MATCH($B10,'Съставки'!$A$2:$A$34,0))) | I10: =IF($B10="",0,INDEX('Съставки'!$G$2:$G$34,MATCH($B10,'Съставки'!$A$2:$A$34,0))) | J10: =IF($B10="",0,INDEX('Съставки'!$H$2:$H$34,MATCH($B10,'Съставки'!$A$2:$A$34,0))) | K10: =IF($B10="",0,INDEX('Съставки'!$I$2:$I$34,MATCH($B10,'Съставки'!$A$2:$A$34,0))) | L10: =IF($B10="",0,INDEX('Съставки'!$J$2:$J$34,MATCH($B10,'Съставки'!$A$2:$A$34,0))) | M10: =IF($B10="",0,INDEX('Съставки'!$K$2:$K$34,MATCH($B10,'Съставки'!$A$2:$A$34,0))) | N10: =IF($B10="",0,INDEX('Съставки'!$L$2:$L$34,MATCH($B10,'Съставки'!$A$2:$A$34,0))) | O10: =IF($B10="",0,INDEX('Съставки'!$M$2:$M$34,MATCH($B10,'Съставки'!$A$2:$A$34,0))) | P10: =IF($B10="",0,INDEX('Съставки'!$N$2:$N$34,MATCH($B10,'Съставки'!$A$2:$A$34,0))) | Q10: =IF($B10="",0,INDEX('Съставки'!$O$2:$O$34,MATCH($B10,'Съставки'!$A$2:$A$34,0))) | R10: =IF($B10="",0,INDEX('Съставки'!$P$2:$P$34,MATCH($B10,'Съставки'!$A$2:$A$34,0))) | S10: =IF($B10="",0,INDEX('Съставки'!$Q$2:$Q$34,MATCH($B10,'Съставки'!$A$2:$A$34,0))) | T10: =IF($B10="",0,INDEX('Съставки'!$R$2:$R$34,MATCH($B10,'Съставки'!$A$2:$A$34,0)))
A11: Чорба Езогелин | B11: Червен пипер (лют) | C11: 0.01 | D11: =IF($B11="","",INDEX('Съставки'!$B$2:$B$34,MATCH($B11,'Съставки'!$A$2:$A$34,0))) | E11: =IF($B11="","",INDEX('Съставки'!$C$2:$C$34,MATCH($B11,'Съставки'!$A$2:$A$34,0))) | F11: =IF($B11="","",$C11*$E11) | G11: =IF($B11="",0,INDEX('Съставки'!$E$2:$E$34,MATCH($B11,'Съставки'!$A$2:$A$34,0))) | H11: =IF($B11="",0,INDEX('Съставки'!$F$2:$F$34,MATCH($B11,'Съставки'!$A$2:$A$34,0))) | I11: =IF($B11="",0,INDEX('Съставки'!$G$2:$G$34,MATCH($B11,'Съставки'!$A$2:$A$34,0))) | J11: =IF($B11="",0,INDEX('Съставки'!$H$2:$H$34,MATCH($B11,'Съставки'!$A$2:$A$34,0))) | K11: =IF($B11="",0,INDEX('Съставки'!$I$2:$I$34,MATCH($B11,'Съставки'!$A$2:$A$34,0))) | L11: =IF($B11="",0,INDEX('Съставки'!$J$2:$J$34,MATCH($B11,'Съставки'!$A$2:$A$34,0))) | M11: =IF($B11="",0,INDEX('Съставки'!$K$2:$K$34,MATCH($B11,'Съставки'!$A$2:$A$34,0))) | N11: =IF($B11="",0,INDEX('Съставки'!$L$2:$L$34,MATCH($B11,'Съставки'!$A$2:$A$34,0))) | O11: =IF($B11="",0,INDEX('Съставки'!$M$2:$M$34,MATCH($B11,'Съставки'!$A$2:$A$34,0))) | P11: =IF($B11="",0,INDEX('Съставки'!$N$2:$N$34,MATCH($B11,'Съставки'!$A$2:$A$34,0))) | Q11: =IF($B11="",0,INDEX('Съставки'!$O$2:$O$34,MATCH($B11,'Съставки'!$A$2:$A$34,0))) | R11: =IF($B11="",0,INDEX('Съставки'!$P$2:$P$34,MATCH($B11,'Съставки'!$A$2:$A$34,0))) | S11: =IF($B11="",0,INDEX('Съставки'!$Q$2:$Q$34,MATCH($B11,'Съставки'!$A$2:$A$34,0))) | T11: =IF($B11="",0,INDEX('Съставки'!$R$2:$R$34,MATCH($B11,'Съставки'!$A$2:$A$34,0)))
A12: Чорба Езогелин | B12: Сол | C12: 0.015 | D12: =IF($B12="","",INDEX('Съставки'!$B$2:$B$34,MATCH($B12,'Съставки'!$A$2:$A$34,0))) | E12: =IF($B12="","",INDEX('Съставки'!$C$2:$C$34,MATCH($B12,'Съставки'!$A$2:$A$34,0))) | F12: =IF($B12="","",$C12*$E12) | G12: =IF($B12="",0,INDEX('Съставки'!$E$2:$E$34,MATCH($B12,'Съставки'!$A$2:$A$34,0))) | H12: =IF($B12="",0,INDEX('Съставки'!$F$2:$F$34,MATCH($B12,'Съставки'!$A$2:$A$34,0))) | I12: =IF($B12="",0,INDEX('Съставки'!$G$2:$G$34,MATCH($B12,'Съставки'!$A$2:$A$34,0))) | J12: =IF($B12="",0,INDEX('Съставки'!$H$2:$H$34,MATCH($B12,'Съставки'!$A$2:$A$34,0))) | K12: =IF($B12="",0,INDEX('Съставки'!$I$2:$I$34,MATCH($B12,'Съставки'!$A$2:$A$34,0))) | L12: =IF($B12="",0,INDEX('Съставки'!$J$2:$J$34,MATCH($B12,'Съставки'!$A$2:$A$34,0))) | M12: =IF($B12="",0,INDEX('Съставки'!$K$2:$K$34,MATCH($B12,'Съставки'!$A$2:$A$34,0))) | N12: =IF($B12="",0,INDEX('Съставки'!$L$2:$L$34,MATCH($B12,'Съставки'!$A$2:$A$34,0))) | O12: =IF($B12="",0,INDEX('Съставки'!$M$2:$M$34,MATCH($B12,'Съставки'!$A$2:$A$34,0))) | P12: =IF($B12="",0,INDEX('Съставки'!$N$2:$N$34,MATCH($B12,'Съставки'!$A$2:$A$34,0))) | Q12: =IF($B12="",0,INDEX('Съставки'!$O$2:$O$34,MATCH($B12,'Съставки'!$A$2:$A$34,0))) | R12: =IF($B12="",0,INDEX('Съставки'!$P$2:$P$34,MATCH($B12,'Съставки'!$A$2:$A$34,0))) | S12: =IF($B12="",0,INDEX('Съставки'!$Q$2:$Q$34,MATCH($B12,'Съставки'!$A$2:$A$34,0))) | T12: =IF($B12="",0,INDEX('Съставки'!$R$2:$R$34,MATCH($B12,'Съставки'!$A$2:$A$34,0)))
A13: Чорба Езогелин | B13: Вода | C13: 2 | D13: =IF($B13="","",INDEX('Съставки'!$B$2:$B$34,MATCH($B13,'Съставки'!$A$2:$A$34,0))) | E13: =IF($B13="","",INDEX('Съставки'!$C$2:$C$34,MATCH($B13,'Съставки'!$A$2:$A$34,0))) | F13: =IF($B13="","",$C13*$E13) | G13: =IF($B13="",0,INDEX('Съставки'!$E$2:$E$34,MATCH($B13,'Съставки'!$A$2:$A$34,0))) | H13: =IF($B13="",0,INDEX('Съставки'!$F$2:$F$34,MATCH($B13,'Съставки'!$A$2:$A$34,0))) | I13: =IF($B13="",0,INDEX('Съставки'!$G$2:$G$34,MATCH($B13,'Съставки'!$A$2:$A$34,0))) | J13: =IF($B13="",0,INDEX('Съставки'!$H$2:$H$34,MATCH($B13,'Съставки'!$A$2:$A$34,0))) | K13: =IF($B13="",0,INDEX('Съставки'!$I$2:$I$34,MATCH($B13,'Съставки'!$A$2:$A$34,0))) | L13: =IF($B13="",0,INDEX('Съставки'!$J$2:$J$34,MATCH($B13,'Съставки'!$A$2:$A$34,0))) | M13: =IF($B13="",0,INDEX('Съставки'!$K$2:$K$34,MATCH($B13,'Съставки'!$A$2:$A$34,0))) | N13: =IF($B13="",0,INDEX('Съставки'!$L$2:$L$34,MATCH($B13,'Съставки'!$A$2:$A$34,0))) | O13: =IF($B13="",0,INDEX('Съставки'!$M$2:$M$34,MATCH($B13,'Съставки'!$A$2:$A$34,0))) | P13: =IF($B13="",0,INDEX('Съставки'!$N$2:$N$34,MATCH($B13,'Съставки'!$A$2:$A$34,0))) | Q13: =IF($B13="",0,INDEX('Съставки'!$O$2:$O$34,MATCH($B13,'Съставки'!$A$2:$A$34,0))) | R13: =IF($B13="",0,INDEX('Съставки'!$P$2:$P$34,MATCH($B13,'Съставки'!$A$2:$A$34,0))) | S13: =IF($B13="",0,INDEX('Съставки'!$Q$2:$Q$34,MATCH($B13,'Съставки'!$A$2:$A$34,0))) | T13: =IF($B13="",0,INDEX('Съставки'!$R$2:$R$34,MATCH($B13,'Съставки'!$A$2:$A$34,0)))
A14: ОБЩА СЕБЕСТОЙНОСТ: | F14: =SUM(F6:F13)
A16: Мезе плато (турско) / Turkish Meze Platter
A17: Категория: | B17: Предястия | C17: Порции: | D17: =INDEX('Рецепти'!$E:$E,3) | E17: Себестойност/порция: | F17: =INDEX('Рецепти'!$G:$G,3)
A18: Приготвяне: Подредете киселото мляко, нарязаните краставици и домати, телемеята и маслините в отделни секции на плато. Поднесете с топла пита.
A19: Ястие (за справка) | B19: Съставка | C19: Количество | D19: Мярка | E19: Цена/ед. (лв) | F19: Стойност (лв)
A20: Мезе плато (турско) | B20: Кисело мляко | C20: 0.3 | D20: =IF($B20="","",INDEX('Съставки'!$B$2:$B$34,MATCH($B20,'Съставки'!$A$2:$A$34,0))) | E20: =IF($B20="","",INDEX('Съставки'!$C$2:$C$34,MATCH($B20,'Съставки'!$A$2:$A$34,0))) | F20: =IF($B20="","",$C20*$E20) | G20: =IF($B20="",0,INDEX('Съставки'!$E$2:$E$34,MATCH($B20,'Съставки'!$A$2:$A$34,0))) | H20: =IF($B20="",0,INDEX('Съставки'!$F$2:$F$34,MATCH($B20,'Съставки'!$A$2:$A$34,0))) | I20: =IF($B20="",0,INDEX('Съставки'!$G$2:$G$34,MATCH($B20,'Съставки'!$A$2:$A$34,0))) | J20: =IF($B20="",0,INDEX('Съставки'!$H$2:$H$34,MATCH($B20,'Съставки'!$A$2:$A$34,0))) | K20: =IF($B20="",0,INDEX('Съставки'!$I$2:$I$34,MATCH($B20,'Съставки'!$A$2:$A$34,0))) | L20: =IF($B20="",0,INDEX('Съставки'!$J$2:$J$34,MATCH($B20,'Съставки'!$A$2:$A$34,0))) | M20: =IF($B20="",0,INDEX('Съставки'!$K$2:$K$34,MATCH($B20,'Съставки'!$A$2:$A$34,0))) | N20: =IF($B20="",0,INDEX('Съставки'!$L$2:$L$34,MATCH($B20,'Съставки'!$A$2:$A$34,0))) | O20: =IF($B20="",0,INDEX('Съставки'!$M$2:$M$34,MATCH($B20,'Съставки'!$A$2:$A$34,0))) | P20: =IF($B20="",0,INDEX('Съставки'!$N$2:$N$34,MATCH($B20,'Съставки'!$A$2:$A$34,0))) | Q20: =IF($B20="",0,INDEX('Съставки'!$O$2:$O$34,MATCH($B20,'Съставки'!$A$2:$A$34,0))) | R20: =IF($B20="",0,INDEX('Съставки'!$P$2:$P$34,MATCH($B20,'Съставки'!$A$2:$A$34,0))) | S20: =IF($B20="",0,INDEX('Съставки'!$Q$2:$Q$34,MATCH($B20,'Съставки'!$A$2:$A$34,0))) | T20: =IF($B20="",0,INDEX('Съставки'!$R$2:$R$34,MATCH($B20,'Съставки'!$A$2:$A$34,0)))
A21: Мезе плато (турско) | B21: Краставици | C21: 0.2 | D21: =IF($B21="","",INDEX('Съставки'!$B$2:$B$34,MATCH($B21,'Съставки'!$A$2:$A$34,0))) | E21: =IF($B21="","",INDEX('Съставки'!$C$2:$C$34,MATCH($B21,'Съставки'!$A$2:$A$34,0))) | F21: =IF($B21="","",$C21*$E21) | G21: =IF($B21="",0,INDEX('Съставки'!$E$2:$E$34,MATCH($B21,'Съставки'!$A$2:$A$34,0))) | H21: =IF($B21="",0,INDEX('Съставки'!$F$2:$F$34,MATCH($B21,'Съставки'!$A$2:$A$34,0))) | I21: =IF($B21="",0,INDEX('Съставки'!$G$2:$G$34,MATCH($B21,'Съставки'!$A$2:$A$34,0))) | J21: =IF($B21="",0,INDEX('Съставки'!$H$2:$H$34,MATCH($B21,'Съставки'!$A$2:$A$34,0))) | K21: =IF($B21="",0,INDEX('Съставки'!$I$2:$I$34,MATCH($B21,'Съставки'!$A$2:$A$34,0))) | L21: =IF($B21="",0,INDEX('Съставки'!$J$2:$J$34,MATCH($B21,'Съставки'!$A$2:$A$34,0))) | M21: =IF($B21="",0,INDEX('Съставки'!$K$2:$K$34,MATCH($B21,'Съставки'!$A$2:$A$34,0))) | N21: =IF($B21="",0,INDEX('Съставки'!$L$2:$L$34,MATCH($B21,'Съставки'!$A$2:$A$34,0))) | O21: =IF($B21="",0,INDEX('Съставки'!$M$2:$M$34,MATCH($B21,'Съставки'!$A$2:$A$34,0))) | P21: =IF($B21="",0,INDEX('Съставки'!$N$2:$N$34,MATCH($B21,'Съставки'!$A$2:$A$34,0))) | Q21: =IF($B21="",0,INDEX('Съставки'!$O$2:$O$34,MATCH($B21,'Съставки'!$A$2:$A$34,0))) | R21: =IF($B21="",0,INDEX('Съставки'!$P$2:$P$34,MATCH($B21,'Съставки'!$A$2:$A$34,0))) | S21: =IF($B21="",0,INDEX('Съставки'!$Q$2:$Q$34,MATCH($B21,'Съставки'!$A$2:$A$34,0))) | T21: =IF($B21="",0,INDEX('Съставки'!$R$2:$R$34,MATCH($B21,'Съставки'!$A$2:$A$34,0)))
A22: Мезе плато (турско) | B22: Чесън | C22: 0.02 | D22: =IF($B22="","",INDEX('Съставки'!$B$2:$B$34,MATCH($B22,'Съставки'!$A$2:$A$34,0))) | E22: =IF($B22="","",INDEX('Съставки'!$C$2:$C$34,MATCH($B22,'Съставки'!$A$2:$A$34,0))) | F22: =IF($B22="","",$C22*$E22) | G22: =IF($B22="",0,INDEX('Съставки'!$E$2:$E$34,MATCH($B22,'Съставки'!$A$2:$A$34,0))) | H22: =IF($B22="",0,INDEX('Съставки'!$F$2:$F$34,MATCH($B22,'Съставки'!$A$2:$A$34,0))) | I22: =IF($B22="",0,INDEX('Съставки'!$G$2:$G$34,MATCH($B22,'Съставки'!$A$2:$A$34,0))) | J22: =IF($B22="",0,INDEX('Съставки'!$H$2:$H$34,MATCH($B22,'Съставки'!$A$2:$A$34,0))) | K22: =IF($B22="",0,INDEX('Съставки'!$I$2:$I$34,MATCH($B22,'Съставки'!$A$2:$A$34,0))) | L22: =IF($B22="",0,INDEX('Съставки'!$J$2:$J$34,MATCH($B22,'Съставки'!$A$2:$A$34,0))) | M22: =IF($B22="",0,INDEX('Съставки'!$K$2:$K$34,MATCH($B22,'Съставки'!$A$2:$A$34,0))) | N22: =IF($B22="",0,INDEX('Съставки'!$L$2:$L$34,MATCH($B22,'Съставки'!$A$2:$A$34,0))) | O22: =IF($B22="",0,INDEX('Съставки'!$M$2:$M$34,MATCH($B22,'Съставки'!$A$2:$A$34,0))) | P22: =IF($B22="",0,INDEX('Съставки'!$N$2:$N$34,MATCH($B22,'Съставки'!$A$2:$A$34,0))) | Q22: =IF($B22="",0,INDEX('Съставки'!$O$2:$O$34,MATCH($B22,'Съставки'!$A$2:$A$34,0))) | R22: =IF($B22="",0,INDEX('Съставки'!$P$2:$P$34,MATCH($B22,'Съставки'!$A$2:$A$34,0))) | S22: =IF($B22="",0,INDEX('Съставки'!$Q$2:$Q$34,MATCH($B22,'Съставки'!$A$2:$A$34,0))) | T22: =IF($B22="",0,INDEX('Съставки'!$R$2:$R$34,MATCH($B22,'Съставки'!$A$2:$A$34,0)))
A23: Мезе плато (турско) | B23: Сирене телемея | C23: 0.2 | D23: =IF($B23="","",INDEX('Съставки'!$B$2:$B$34,MATCH($B23,'Съставки'!$A$2:$A$34,0))) | E23: =IF($B23="","",INDEX('Съставки'!$C$2:$C$34,MATCH($B23,'Съставки'!$A$2:$A$34,0))) | F23: =IF($B23="","",$C23*$E23) | G23: =IF($B23="",0,INDEX('Съставки'!$E$2:$E$34,MATCH($B23,'Съставки'!$A$2:$A$34,0))) | H23: =IF($B23="",0,INDEX('Съставки'!$F$2:$F$34,MATCH($B23,'Съставки'!$A$2:$A$34,0))) | I23: =IF($B23="",0,INDEX('Съставки'!$G$2:$G$34,MATCH($B23,'Съставки'!$A$2:$A$34,0))) | J23: =IF($B23="",0,INDEX('Съставки'!$H$2:$H$34,MATCH($B23,'Съставки'!$A$2:$A$34,0))) | K23: =IF($B23="",0,INDEX('Съставки'!$I$2:$I$34,MATCH($B23,'Съставки'!$A$2:$A$34,0))) | L23: =IF($B23="",0,INDEX('Съставки'!$J$2:$J$34,MATCH($B23,'Съставки'!$A$2:$A$34,0))) | M23: =IF($B23="",0,INDEX('Съставки'!$K$2:$K$34,MATCH($B23,'Съставки'!$A$2:$A$34,0))) | N23: =IF($B23="",0,INDEX('Съставки'!$L$2:$L$34,MATCH($B23,'Съставки'!$A$2:$A$34,0))) | O23: =IF($B23="",0,INDEX('Съставки'!$M$2:$M$34,MATCH($B23,'Съставки'!$A$2:$A$34,0))) | P23: =IF($B23="",0,INDEX('Съставки'!$N$2:$N$34,MATCH($B23,'Съставки'!$A$2:$A$34,0))) | Q23: =IF($B23="",0,INDEX('Съставки'!$O$2:$O$34,MATCH($B23,'Съставки'!$A$2:$A$34,0))) | R23: =IF($B23="",0,INDEX('Съставки'!$P$2:$P$34,MATCH($B23,'Съставки'!$A$2:$A$34,0))) | S23: =IF($B23="",0,INDEX('Съставки'!$Q$2:$Q$34,MATCH($B23,'Съставки'!$A$2:$A$34,0))) | T23: =IF($B23="",0,INDEX('Съставки'!$R$2:$R$34,MATCH($B23,'Съставки'!$A$2:$A$34,0)))
A24: Мезе плато (турско) | B24: Домати | C24: 0.2 | D24: =IF($B24="","",INDEX('Съставки'!$B$2:$B$34,MATCH($B24,'Съставки'!$A$2:$A$34,0))) | E24: =IF($B24="","",INDEX('Съставки'!$C$2:$C$34,MATCH($B24,'Съставки'!$A$2:$A$34,0))) | F24: =IF($B24="","",$C24*$E24) | G24: =IF($B24="",0,INDEX('Съставки'!$E$2:$E$34,MATCH($B24,'Съставки'!$A$2:$A$34,0))) | H24: =IF($B24="",0,INDEX('Съставки'!$F$2:$F$34,MATCH($B24,'Съставки'!$A$2:$A$34,0))) | I24: =IF($B24="",0,INDEX('Съставки'!$G$2:$G$34,MATCH($B24,'Съставки'!$A$2:$A$34,0))) | J24: =IF($B24="",0,INDEX('Съставки'!$H$2:$H$34,MATCH($B24,'Съставки'!$A$2:$A$34,0))) | K24: =IF($B24="",0,INDEX('Съставки'!$I$2:$I$34,MATCH($B24,'Съставки'!$A$2:$A$34,0))) | L24: =IF($B24="",0,INDEX('Съставки'!$J$2:$J$34,MATCH($B24,'Съставки'!$A$2:$A$34,0))) | M24: =IF($B24="",0,INDEX('Съставки'!$K$2:$K$34,MATCH($B24,'Съставки'!$A$2:$A$34,0))) | N24: =IF($B24="",0,INDEX('Съставки'!$L$2:$L$34,MATCH($B24,'Съставки'!$A$2:$A$34,0))) | O24: =IF($B24="",0,INDEX('Съставки'!$M$2:$M$34,MATCH($B24,'Съставки'!$A$2:$A$34,0))) | P24: =IF($B24="",0,INDEX('Съставки'!$N$2:$N$34,MATCH($B24,'Съставки'!$A$2:$A$34,0))) | Q24: =IF($B24="",0,INDEX('Съставки'!$O$2:$O$34,MATCH($B24,'Съставки'!$A$2:$A$34,0))) | R24: =IF($B24="",0,INDEX('Съставки'!$P$2:$P$34,MATCH($B24,'Съставки'!$A$2:$A$34,0))) | S24: =IF($B24="",0,INDEX('Съставки'!$Q$2:$Q$34,MATCH($B24,'Съставки'!$A$2:$A$34,0))) | T24: =IF($B24="",0,INDEX('Съставки'!$R$2:$R$34,MATCH($B24,'Съставки'!$A$2:$A$34,0)))
A25: Мезе плато (турско) | B25: Маслини | C25: 0.15 | D25: =IF($B25="","",INDEX('Съставки'!$B$2:$B$34,MATCH($B25,'Съставки'!$A$2:$A$34,0))) | E25: =IF($B25="","",INDEX('Съставки'!$C$2:$C$34,MATCH($B25,'Съставки'!$A$2:$A$34,0))) | F25: =IF($B25="","",$C25*$E25) | G25: =IF($B25="",0,INDEX('Съставки'!$E$2:$E$34,MATCH($B25,'Съставки'!$A$2:$A$34,0))) | H25: =IF($B25="",0,INDEX('Съставки'!$F$2:$F$34,MATCH($B25,'Съставки'!$A$2:$A$34,0))) | I25: =IF($B25="",0,INDEX('Съставки'!$G$2:$G$34,MATCH($B25,'Съставки'!$A$2:$A$34,0))) | J25: =IF($B25="",0,INDEX('Съставки'!$H$2:$H$34,MATCH($B25,'Съставки'!$A$2:$A$34,0))) | K25: =IF($B25="",0,INDEX('Съставки'!$I$2:$I$34,MATCH($B25,'Съставки'!$A$2:$A$34,0))) | L25: =IF($B25="",0,INDEX('Съставки'!$J$2:$J$34,MATCH($B25,'Съставки'!$A$2:$A$34,0))) | M25: =IF($B25="",0,INDEX('Съставки'!$K$2:$K$34,MATCH($B25,'Съставки'!$A$2:$A$34,0))) | N25: =IF($B25="",0,INDEX('Съставки'!$L$2:$L$34,MATCH($B25,'Съставки'!$A$2:$A$34,0))) | O25: =IF($B25="",0,INDEX('Съставки'!$M$2:$M$34,MATCH($B25,'Съставки'!$A$2:$A$34,0))) | P25: =IF($B25="",0,INDEX('Съставки'!$N$2:$N$34,MATCH($B25,'Съставки'!$A$2:$A$34,0))) | Q25: =IF($B25="",0,INDEX('Съставки'!$O$2:$O$34,MATCH($B25,'Съставки'!$A$2:$A$34,0))) | R25: =IF($B25="",0,INDEX('Съставки'!$P$2:$P$34,MATCH($B25,'Съставки'!$A$2:$A$34,0))) | S25: =IF($B25="",0,INDEX('Съставки'!$Q$2:$Q$34,MATCH($B25,'Съставки'!$A$2:$A$34,0))) | T25: =IF($B25="",0,INDEX('Съставки'!$R$2:$R$34,MATCH($B25,'Съставки'!$A$2:$A$34,0)))
A26: Мезе плато (турско) | B26: Олио | C26: 0.05 | D26: =IF($B26="","",INDEX('Съставки'!$B$2:$B$34,MATCH($B26,'Съставки'!$A$2:$A$34,0))) | E26: =IF($B26="","",INDEX('Съставки'!$C$2:$C$34,MATCH($B26,'Съставки'!$A$2:$A$34,0))) | F26: =IF($B26="","",$C26*$E26) | G26: =IF($B26="",0,INDEX('Съставки'!$E$2:$E$34,MATCH($B26,'Съставки'!$A$2:$A$34,0))) | H26: =IF($B26="",0,INDEX('Съставки'!$F$2:$F$34,MATCH($B26,'Съставки'!$A$2:$A$34,0))) | I26: =IF($B26="",0,INDEX('Съставки'!$G$2:$G$34,MATCH($B26,'Съставки'!$A$2:$A$34,0))) | J26: =IF($B26="",0,INDEX('Съставки'!$H$2:$H$34,MATCH($B26,'Съставки'!$A$2:$A$34,0))) | K26: =IF($B26="",0,INDEX('Съставки'!$I$2:$I$34,MATCH($B26,'Съставки'!$A$2:$A$34,0))) | L26: =IF($B26="",0,INDEX('Съставки'!$J$2:$J$34,MATCH($B26,'Съставки'!$A$2:$A$34,0))) | M26: =IF($B26="",0,INDEX('Съставки'!$K$2:$K$34,MATCH($B26,'Съставки'!$A$2:$A$34,0))) | N26: =IF($B26="",0,INDEX('Съставки'!$L$2:$L$34,MATCH($B26,'Съставки'!$A$2:$A$34,0))) | O26: =IF($B26="",0,INDEX('Съставки'!$M$2:$M$34,MATCH($B26,'Съставки'!$A$2:$A$34,0))) | P26: =IF($B26="",0,INDEX('Съставки'!$N$2:$N$34,MATCH($B26,'Съставки'!$A$2:$A$34,0))) | Q26: =IF($B26="",0,INDEX('Съставки'!$O$2:$O$34,MATCH($B26,'Съставки'!$A$2:$A$34,0))) | R26: =IF($B26="",0,INDEX('Съставки'!$P$2:$P$34,MATCH($B26,'Съставки'!$A$2:$A$34,0))) | S26: =IF($B26="",0,INDEX('Съставки'!$Q$2:$Q$34,MATCH($B26,'Съставки'!$A$2:$A$34,0))) | T26: =IF($B26="",0,INDEX('Съставки'!$R$2:$R$34,MATCH($B26,'Съставки'!$A$2:$A$34,0)))
A27: Мезе плато (турско) | B27: Пита хляб | C27: 4 | D27: =IF($B27="","",INDEX('Съставки'!$B$2:$B$34,MATCH($B27,'Съставки'!$A$2:$A$34,0))) | E27: =IF($B27="","",INDEX('Съставки'!$C$2:$C$34,MATCH($B27,'Съставки'!$A$2:$A$34,0))) | F27: =IF($B27="","",$C27*$E27) | G27: =IF($B27="",0,INDEX('Съставки'!$E$2:$E$34,MATCH($B27,'Съставки'!$A$2:$A$34,0))) | H27: =IF($B27="",0,INDEX('Съставки'!$F$2:$F$34,MATCH($B27,'Съставки'!$A$2:$A$34,0))) | I27: =IF($B27="",0,INDEX('Съставки'!$G$2:$G$34,MATCH($B27,'Съставки'!$A$2:$A$34,0))) | J27: =IF($B27="",0,INDEX('Съставки'!$H$2:$H$34,MATCH($B27,'Съставки'!$A$2:$A$34,0))) | K27: =IF($B27="",0,INDEX('Съставки'!$I$2:$I$34,MATCH($B27,'Съставки'!$A$2:$A$34,0))) | L27: =IF($B27="",0,INDEX('Съставки'!$J$2:$J$34,MATCH($B27,'Съставки'!$A$2:$A$34,0))) | M27: =IF($B27="",0,INDEX('Съставки'!$K$2:$K$34,MATCH($B27,'Съставки'!$A$2:$A$34,0))) | N27: =IF($B27="",0,INDEX('Съставки'!$L$2:$L$34,MATCH($B27,'Съставки'!$A$2:$A$34,0))) | O27: =IF($B27="",0,INDEX('Съставки'!$M$2:$M$34,MATCH($B27,'Съставки'!$A$2:$A$34,0))) | P27: =IF($B27="",0,INDEX('Съставки'!$N$2:$N$34,MATCH($B27,'Съставки'!$A$2:$A$34,0))) | Q27: =IF($B27="",0,INDEX('Съставки'!$O$2:$O$34,MATCH($B27,'Съставки'!$A$2:$A$34,0))) | R27: =IF($B27="",0,INDEX('Съставки'!$P$2:$P$34,MATCH($B27,'Съставки'!$A$2:$A$34,0))) | S27: =IF($B27="",0,INDEX('Съставки'!$Q$2:$Q$34,MATCH($B27,'Съставки'!$A$2:$A$34,0))) | T27: =IF($B27="",0,INDEX('Съставки'!$R$2:$R$34,MATCH($B27,'Съставки'!$A$2:$A$34,0)))
A28: ОБЩА СЕБЕСТОЙНОСТ: | F28: =SUM(F20:F27)
A30: Искендер кебап / Iskender Kebab
A31: Категория: | B31: Основни | C31: Порции: | D31: =INDEX('Рецепти'!$E:$E,4) | E31: Себестойност/порция: | F31: =INDEX('Рецепти'!$G:$G,4)
A32: Приготвяне: Нарежете питата на хапки в дъното на чинията. Наредете отгоре дюнер месото, залейте с горещ доматен сос и топено масло, поднесете с кисело мляко отстрани.
A33: Ястие (за справка) | B33: Съставка | C33: Количество | D33: Мярка | E33: Цена/ед. (лв) | F33: Стойност (лв)
A34: Искендер кебап | B34: Телешко месо (филе за дюнер) | C34: 0.6 | D34: =IF($B34="","",INDEX('Съставки'!$B$2:$B$34,MATCH($B34,'Съставки'!$A$2:$A$34,0))) | E34: =IF($B34="","",INDEX('Съставки'!$C$2:$C$34,MATCH($B34,'Съставки'!$A$2:$A$34,0))) | F34: =IF($B34="","",$C34*$E34) | G34: =IF($B34="",0,INDEX('Съставки'!$E$2:$E$34,MATCH($B34,'Съставки'!$A$2:$A$34,0))) | H34: =IF($B34="",0,INDEX('Съставки'!$F$2:$F$34,MATCH($B34,'Съставки'!$A$2:$A$34,0))) | I34: =IF($B34="",0,INDEX('Съставки'!$G$2:$G$34,MATCH($B34,'Съставки'!$A$2:$A$34,0))) | J34: =IF($B34="",0,INDEX('Съставки'!$H$2:$H$34,MATCH($B34,'Съставки'!$A$2:$A$34,0))) | K34: =IF($B34="",0,INDEX('Съставки'!$I$2:$I$34,MATCH($B34,'Съставки'!$A$2:$A$34,0))) | L34: =IF($B34="",0,INDEX('Съставки'!$J$2:$J$34,MATCH($B34,'Съставки'!$A$2:$A$34,0))) | M34: =IF($B34="",0,INDEX('Съставки'!$K$2:$K$34,MATCH($B34,'Съставки'!$A$2:$A$34,0))) | N34: =IF($B34="",0,INDEX('Съставки'!$L$2:$L$34,MATCH($B34,'Съставки'!$A$2:$A$34,0))) | O34: =IF($B34="",0,INDEX('Съставки'!$M$2:$M$34,MATCH($B34,'Съставки'!$A$2:$A$34,0))) | P34: =IF($B34="",0,INDEX('Съставки'!$N$2:$N$34,MATCH($B34,'Съставки'!$A$2:$A$34,0))) | Q34: =IF($B34="",0,INDEX('Съставки'!$O$2:$O$34,MATCH($B34,'Съставки'!$A$2:$A$34,0))) | R34: =IF($B34="",0,INDEX('Съставки'!$P$2:$P$34,MATCH($B34,'Съставки'!$A$2:$A$34,0))) | S34: =IF($B34="",0,INDEX('Съставки'!$Q$2:$Q$34,MATCH($B34,'Съставки'!$A$2:$A$34,0))) | T34: =IF($B34="",0,INDEX('Съставки'!$R$2:$R$34,MATCH($B34,'Съставки'!$A$2:$A$34,0)))
A35: Искендер кебап | B35: Пита хляб | C35: 4 | D35: =IF($B35="","",INDEX('Съставки'!$B$2:$B$34,MATCH($B35,'Съставки'!$A$2:$A$34,0))) | E35: =IF($B35="","",INDEX('Съставки'!$C$2:$C$34,MATCH($B35,'Съставки'!$A$2:$A$34,0))) | F35: =IF($B35="","",$C35*$E35) | G35: =IF($B35="",0,INDEX('Съставки'!$E$2:$E$34,MATCH($B35,'Съставки'!$A$2:$A$34,0))) | H35: =IF($B35="",0,INDEX('Съставки'!$F$2:$F$34,MATCH($B35,'Съставки'!$A$2:$A$34,0))) | I35: =IF($B35="",0,INDEX('Съставки'!$G$2:$G$34,MATCH($B35,'Съставки'!$A$2:$A$34,0))) | J35: =IF($B35="",0,INDEX('Съставки'!$H$2:$H$34,MATCH($B35,'Съставки'!$A$2:$A$34,0))) | K35: =IF($B35="",0,INDEX('Съставки'!$I$2:$I$34,MATCH($B35,'Съставки'!$A$2:$A$34,0))) | L35: =IF($B35="",0,INDEX('Съставки'!$J$2:$J$34,MATCH($B35,'Съставки'!$A$2:$A$34,0))) | M35: =IF($B35="",0,INDEX('Съставки'!$K$2:$K$34,MATCH($B35,'Съставки'!$A$2:$A$34,0))) | N35: =IF($B35="",0,INDEX('Съставки'!$L$2:$L$34,MATCH($B35,'Съставки'!$A$2:$A$34,0))) | O35: =IF($B35="",0,INDEX('Съставки'!$M$2:$M$34,MATCH($B35,'Съставки'!$A$2:$A$34,0))) | P35: =IF($B35="",0,INDEX('Съставки'!$N$2:$N$34,MATCH($B35,'Съставки'!$A$2:$A$34,0))) | Q35: =IF($B35="",0,INDEX('Съставки'!$O$2:$O$34,MATCH($B35,'Съставки'!$A$2:$A$34,0))) | R35: =IF($B35="",0,INDEX('Съставки'!$P$2:$P$34,MATCH($B35,'Съставки'!$A$2:$A$34,0))) | S35: =IF($B35="",0,INDEX('Съставки'!$Q$2:$Q$34,MATCH($B35,'Съставки'!$A$2:$A$34,0))) | T35: =IF($B35="",0,INDEX('Съставки'!$R$2:$R$34,MATCH($B35,'Съставки'!$A$2:$A$34,0)))
A36: Искендер кебап | B36: Кисело мляко | C36: 0.3 | D36: =IF($B36="","",INDEX('Съставки'!$B$2:$B$34,MATCH($B36,'Съставки'!$A$2:$A$34,0))) | E36: =IF($B36="","",INDEX('Съставки'!$C$2:$C$34,MATCH($B36,'Съставки'!$A$2:$A$34,0))) | F36: =IF($B36="","",$C36*$E36) | G36: =IF($B36="",0,INDEX('Съставки'!$E$2:$E$34,MATCH($B36,'Съставки'!$A$2:$A$34,0))) | H36: =IF($B36="",0,INDEX('Съставки'!$F$2:$F$34,MATCH($B36,'Съставки'!$A$2:$A$34,0))) | I36: =IF($B36="",0,INDEX('Съставки'!$G$2:$G$34,MATCH($B36,'Съставки'!$A$2:$A$34,0))) | J36: =IF($B36="",0,INDEX('Съставки'!$H$2:$H$34,MATCH($B36,'Съставки'!$A$2:$A$34,0))) | K36: =IF($B36="",0,INDEX('Съставки'!$I$2:$I$34,MATCH($B36,'Съставки'!$A$2:$A$34,0))) | L36: =IF($B36="",0,INDEX('Съставки'!$J$2:$J$34,MATCH($B36,'Съставки'!$A$2:$A$34,0))) | M36: =IF($B36="",0,INDEX('Съставки'!$K$2:$K$34,MATCH($B36,'Съставки'!$A$2:$A$34,0))) | N36: =IF($B36="",0,INDEX('Съставки'!$L$2:$L$34,MATCH($B36,'Съставки'!$A$2:$A$34,0))) | O36: =IF($B36="",0,INDEX('Съставки'!$M$2:$M$34,MATCH($B36,'Съставки'!$A$2:$A$34,0))) | P36: =IF($B36="",0,INDEX('Съставки'!$N$2:$N$34,MATCH($B36,'Съставки'!$A$2:$A$34,0))) | Q36: =IF($B36="",0,INDEX('Съставки'!$O$2:$O$34,MATCH($B36,'Съставки'!$A$2:$A$34,0))) | R36: =IF($B36="",0,INDEX('Съставки'!$P$2:$P$34,MATCH($B36,'Съставки'!$A$2:$A$34,0))) | S36: =IF($B36="",0,INDEX('Съставки'!$Q$2:$Q$34,MATCH($B36,'Съставки'!$A$2:$A$34,0))) | T36: =IF($B36="",0,INDEX('Съставки'!$R$2:$R$34,MATCH($B36,'Съставки'!$A$2:$A$34,0)))
A37: Искендер кебап | B37: Домат паста | C37: 0.1 | D37: =IF($B37="","",INDEX('Съставки'!$B$2:$B$34,MATCH($B37,'Съставки'!$A$2:$A$34,0))) | E37: =IF($B37="","",INDEX('Съставки'!$C$2:$C$34,MATCH($B37,'Съставки'!$A$2:$A$34,0))) | F37: =IF($B37="","",$C37*$E37) | G37: =IF($B37="",0,INDEX('Съставки'!$E$2:$E$34,MATCH($B37,'Съставки'!$A$2:$A$34,0))) | H37: =IF($B37="",0,INDEX('Съставки'!$F$2:$F$34,MATCH($B37,'Съставки'!$A$2:$A$34,0))) | I37: =IF($B37="",0,INDEX('Съставки'!$G$2:$G$34,MATCH($B37,'Съставки'!$A$2:$A$34,0))) | J37: =IF($B37="",0,INDEX('Съставки'!$H$2:$H$34,MATCH($B37,'Съставки'!$A$2:$A$34,0))) | K37: =IF($B37="",0,INDEX('Съставки'!$I$2:$I$34,MATCH($B37,'Съставки'!$A$2:$A$34,0))) | L37: =IF($B37="",0,INDEX('Съставки'!$J$2:$J$34,MATCH($B37,'Съставки'!$A$2:$A$34,0))) | M37: =IF($B37="",0,INDEX('Съставки'!$K$2:$K$34,MATCH($B37,'Съставки'!$A$2:$A$34,0))) | N37: =IF($B37="",0,INDEX('Съставки'!$L$2:$L$34,MATCH($B37,'Съставки'!$A$2:$A$34,0))) | O37: =IF($B37="",0,INDEX('Съставки'!$M$2:$M$34,MATCH($B37,'Съставки'!$A$2:$A$34,0))) | P37: =IF($B37="",0,INDEX('Съставки'!$N$2:$N$34,MATCH($B37,'Съставки'!$A$2:$A$34,0))) | Q37: =IF($B37="",0,INDEX('Съставки'!$O$2:$O$34,MATCH($B37,'Съставки'!$A$2:$A$34,0))) | R37: =IF($B37="",0,INDEX('Съставки'!$P$2:$P$34,MATCH($B37,'Съставки'!$A$2:$A$34,0))) | S37: =IF($B37="",0,INDEX('Съставки'!$Q$2:$Q$34,MATCH($B37,'Съставки'!$A$2:$A$34,0))) | T37: =IF($B37="",0,INDEX('Съставки'!$R$2:$R$34,MATCH($B37,'Съставки'!$A$2:$A$34,0)))
A38: Искендер кебап | B38: Масло | C38: 0.08 | D38: =IF($B38="","",INDEX('Съставки'!$B$2:$B$34,MATCH($B38,'Съставки'!$A$2:$A$34,0))) | E38: =IF($B38="","",INDEX('Съставки'!$C$2:$C$34,MATCH($B38,'Съставки'!$A$2:$A$34,0))) | F38: =IF($B38="","",$C38*$E38) | G38: =IF($B38="",0,INDEX('Съставки'!$E$2:$E$34,MATCH($B38,'Съставки'!$A$2:$A$34,0))) | H38: =IF($B38="",0,INDEX('Съставки'!$F$2:$F$34,MATCH($B38,'Съставки'!$A$2:$A$34,0))) | I38: =IF($B38="",0,INDEX('Съставки'!$G$2:$G$34,MATCH($B38,'Съставки'!$A$2:$A$34,0))) | J38: =IF($B38="",0,INDEX('Съставки'!$H$2:$H$34,MATCH($B38,'Съставки'!$A$2:$A$34,0))) | K38: =IF($B38="",0,INDEX('Съставки'!$I$2:$I$34,MATCH($B38,'Съставки'!$A$2:$A$34,0))) | L38: =IF($B38="",0,INDEX('Съставки'!$J$2:$J$34,MATCH($B38,'Съставки'!$A$2:$A$34,0))) | M38: =IF($B38="",0,INDEX('Съставки'!$K$2:$K$34,MATCH($B38,'Съставки'!$A$2:$A$34,0))) | N38: =IF($B38="",0,INDEX('Съставки'!$L$2:$L$34,MATCH($B38,'Съставки'!$A$2:$A$34,0))) | O38: =IF($B38="",0,INDEX('Съставки'!$M$2:$M$34,MATCH($B38,'Съставки'!$A$2:$A$34,0))) | P38: =IF($B38="",0,INDEX('Съставки'!$N$2:$N$34,MATCH($B38,'Съставки'!$A$2:$A$34,0))) | Q38: =IF($B38="",0,INDEX('Съставки'!$O$2:$O$34,MATCH($B38,'Съставки'!$A$2:$A$34,0))) | R38: =IF($B38="",0,INDEX('Съставки'!$P$2:$P$34,MATCH($B38,'Съставки'!$A$2:$A$34,0))) | S38: =IF($B38="",0,INDEX('Съставки'!$Q$2:$Q$34,MATCH($B38,'Съставки'!$A$2:$A$34,0))) | T38: =IF($B38="",0,INDEX('Съставки'!$R$2:$R$34,MATCH($B38,'Съставки'!$A$2:$A$34,0)))
A39: Искендер кебап | B39: Домати | C39: 0.15 | D39: =IF($B39="","",INDEX('Съставки'!$B$2:$B$34,MATCH($B39,'Съставки'!$A$2:$A$34,0))) | E39: =IF($B39="","",INDEX('Съставки'!$C$2:$C$34,MATCH($B39,'Съставки'!$A$2:$A$34,0))) | F39: =IF($B39="","",$C39*$E39) | G39: =IF($B39="",0,INDEX('Съставки'!$E$2:$E$34,MATCH($B39,'Съставки'!$A$2:$A$34,0))) | H39: =IF($B39="",0,INDEX('Съставки'!$F$2:$F$34,MATCH($B39,'Съставки'!$A$2:$A$34,0))) | I39: =IF($B39="",0,INDEX('Съставки'!$G$2:$G$34,MATCH($B39,'Съставки'!$A$2:$A$34,0))) | J39: =IF($B39="",0,INDEX('Съставки'!$H$2:$H$34,MATCH($B39,'Съставки'!$A$2:$A$34,0))) | K39: =IF($B39="",0,INDEX('Съставки'!$I$2:$I$34,MATCH($B39,'Съставки'!$A$2:$A$34,0))) | L39: =IF($B39="",0,INDEX('Съставки'!$J$2:$J$34,MATCH($B39,'Съставки'!$A$2:$A$34,0))) | M39: =IF($B39="",0,INDEX('Съставки'!$K$2:$K$34,MATCH($B39,'Съставки'!$A$2:$A$34,0))) | N39: =IF($B39="",0,INDEX('Съставки'!$L$2:$L$34,MATCH($B39,'Съставки'!$A$2:$A$34,0))) | O39: =IF($B39="",0,INDEX('Съставки'!$M$2:$M$34,MATCH($B39,'Съставки'!$A$2:$A$34,0))) | P39: =IF($B39="",0,INDEX('Съставки'!$N$2:$N$34,MATCH($B39,'Съставки'!$A$2:$A$34,0))) | Q39: =IF($B39="",0,INDEX('Съставки'!$O$2:$O$34,MATCH($B39,'Съставки'!$A$2:$A$34,0))) | R39: =IF($B39="",0,INDEX('Съставки'!$P$2:$P$34,MATCH($B39,'Съставки'!$A$2:$A$34,0))) | S39: =IF($B39="",0,INDEX('Съставки'!$Q$2:$Q$34,MATCH($B39,'Съставки'!$A$2:$A$34,0))) | T39: =IF($B39="",0,INDEX('Съставки'!$R$2:$R$34,MATCH($B39,'Съставки'!$A$2:$A$34,0)))
A40: ОБЩА СЕБЕСТОЙНОСТ: | F40: =SUM(F34:F39)
A42: Адана кебап / Adana Kebab
A43: Категория: | B43: Основни | C43: Порции: | D43: =INDEX('Рецепти'!$E:$E,5) | E43: Себестойност/порция: | F43: =INDEX('Рецепти'!$G:$G,5)
A44: Приготвяне: Смесете каймите с подправките и лука, оформете на шишове, изпечете на скара. Поднесете с топла пита.
...

Sheet Рецепти
A1: Рецепта (BG) | B1: Име (EN) | C1: Категория | D1: Описание (за меню) | E1: Порции | F1: Себестойност общо (лв) | G1: Себестойност/порция (лв) | H1: Глутен | I1: Ракообразни | J1: Яйца | K1: Риба | L1: Фъстъци | M1: Соя | N1: Мляко | O1: Ядки | P1: Целина | Q1: Синап | R1: Сусам | S1: Серен диоксид/сулфити | T1: Лупина | U1: Мекотели
A2: Чорба Езогелин | B2: Ezogelin Soup | C2: Предястия | D2: Традиционна турска чорба от червена леща и булгур | E2: 8 | F2: =SUMIF('Кухненска_карта'!$A$2:$A$100,$A2,'Кухненска_карта'!$F$2:$F$100) | G2: =IF($E2=0,0,$F2/$E2) | H2: =IF(SUMIF('Кухненска_карта'!$A$2:$A$100,$A2,'Кухненска_карта'!$G$2:$G$100)>0,"Да","-") | I2: =IF(SUMIF('Кухненска_карта'!$A$2:$A$100,$A2,'Кухненска_карта'!$H$2:$H$100)>0,"Да","-") | J2: =IF(SUMIF('Кухненска_карта'!$A$2:$A$100,$A2,'Кухненска_карта'!$I$2:$I$100)>0,"Да","-") | K2: =IF(SUMIF('Кухненска_карта'!$A$2:$A$100,$A2,'Кухненска_карта'!$J$2:$J$100)>0,"Да","-") | L2: =IF(SUMIF('Кухненска_карта'!$A$2:$A$100,$A2,'Кухненска_карта'!$K$2:$K$100)>0,"Да","-") | M2: =IF(SUMIF('Кухненска_карта'!$A$2:$A$100,$A2,'Кухненска_карта'!$L$2:$L$100)>0,"Да","-") | N2: =IF(SUMIF('Кухненска_карта'!$A$2:$A$100,$A2,'Кухненска_карта'!$M$2:$M$100)>0,"Да","-") | O2: =IF(SUMIF('Кухненска_карта'!$A$2:$A$100,$A2,'Кухненска_карта'!$N$2:$N$100)>0,"Да","-") | P2: =IF(SUMIF('Кухненска_карта'!$A$2:$A$100,$A2,'Кухненска_карта'!$O$2:$O$100)>0,"Да","-") | Q2: =IF(SUMIF('Кухненска_карта'!$A$2:$A$100,$A2,'Кухненска_карта'!$P$2:$P$100)>0,"Да","-") | R2: =IF(SUMIF('Кухненска_карта'!$A$2:$A$100,$A2,'Кухненска_карта'!$Q$2:$Q$100)>0,"Да","-") | S2: =IF(SUMIF('Кухненска_карта'!$A$2:$A$100,$A2,'Кухненска_карта'!$R$2:$R$100)>0,"Да","-") | T2: =IF(SUMIF('Кухненска_карта'!$A$2:$A$100,$A2,'Кухненска_карта'!$S$2:$S$100)>0,"Да","-") | U2: =IF(SUMIF('Кухненска_карта'!$A$2:$A$100,$A2,'Кухненска_карта'!$T$2:$T$100)>0,"Да","-")
A3: Мезе плато (турско) | B3: Turkish Meze Platter | C3: Предястия | D3: Селекция от традиционни турски мезета за споделяне | E3: 4 | F3: =SUMIF('Кухненска_карта'!$A$2:$A$100,$A3,'Кухненска_карта'!$F$2:$F$100) | G3: =IF($E3=0,0,$F3/$E3) | H3: =IF(SUMIF('Кухненска_карта'!$A$2:$A$100,$A3,'Кухненска_карта'!$G$2:$G$100)>0,"Да","-") | I3: =IF(SUMIF('Кухненска_карта'!$A$2:$A$100,$A3,'Кухненска_карта'!$H$2:$H$100)>0,"Да","-") | J3: =IF(SUMIF('Кухненска_карта'!$A$2:$A$100,$A3,'Кухненска_карта'!$I$2:$I$100)>0,"Да","-") | K3: =IF(SUMIF('Кухненска_карта'!$A$2:$A$100,$A3,'Кухненска_карта'!$J$2:$J$100)>0,"Да","-") | L3: =IF(SUMIF('Кухненска_карта'!$A$2:$A$100,$A3,'Кухненска_карта'!$K$2:$K$100)>0,"Да","-") | M3: =IF(SUMIF('Кухненска_карта'!$A$2:$A$100,$A3,'Кухненска_карта'!$L$2:$L$100)>0,"Да","-") | N3: =IF(SUMIF('Кухненска_карта'!$A$2:$A$100,$A3,'Кухненска_карта'!$M$2:$M$100)>0,"Да","-") | O3: =IF(SUMIF('Кухненска_карта'!$A$2:$A$100,$A3,'Кухненска_карта'!$N$2:$N$100)>0,"Да","-") | P3: =IF(SUMIF('Кухненска_карта'!$A$2:$A$100,$A3,'Кухненска_карта'!$O$2:$O$100)>0,"Да","-") | Q3: =IF(SUMIF('Кухненска_карта'!$A$2:$A$100,$A3,'Кухненска_карта'!$P$2:$P$100)>0,"Да","-") | R3: =IF(SUMIF('Кухненска_карта'!$A$2:$A$100,$A3,'Кухненска_карта'!$Q$2:$Q$100)>0,"Да","-") | S3: =IF(SUMIF('Кухненска_карта'!$A$2:$A$100,$A3,'Кухненска_карта'!$R$2:$R$100)>0,"Да","-") | T3: =IF(SUMIF('Кухненска_карта'!$A$2:$A$100,$A3,'Кухненска_карта'!$S$2:$S$100)>0,"Да","-") | U3: =IF(SUMIF('Кухненска_карта'!$A$2:$A$100,$A3,'Кухненска_карта'!$T$2:$T$100)>0,"Да","-")
A4: Искендер кебап | B4: Iskender Kebab | C4: Основни | D4: Дюнер месо върху пита с доматен сос и кисело мляко | E4: 4 | F4: =SUMIF('Кухненска_карта'!$A$2:$A$100,$A4,'Кухненска_карта'!$F$2:$F$100) | G4: =IF($E4=0,0,$F4/$E4) | H4: =IF(SUMIF('Кухненска_карта'!$A$2:$A$100,$A4,'Кухненска_карта'!$G$2:$G$100)>0,"Да","-") | I4: =IF(SUMIF('Кухненска_карта'!$A$2:$A$100,$A4,'Кухненска_карта'!$H$2:$H$100)>0,"Да","-") | J4: =IF(SUMIF('Кухненска_карта'!$A$2:$A$100,$A4,'Кухненска_карта'!$I$2:$I$100)>0,"Да","-") | K4: =IF(SUMIF('Кухненска_карта'!$A$2:$A$100,$A4,'Кухненска_карта'!$J$2:$J$100)>0,"Да","-") | L4: =IF(SUMIF('Кухненска_карта'!$A$2:$A$100,$A4,'Кухненска_карта'!$K$2:$K$100)>0,"Да","-") | M4: =IF(SUMIF('Кухненска_карта'!$A$2:$A$100,$A4,'Кухненска_карта'!$L$2:$L$100)>0,"Да","-") | N4: =IF(SUMIF('Кухненска_карта'!$A$2:$A$100,$A4,'Кухненска_карта'!$M$2:$M$100)>0,"Да","-") | O4: =IF(SUMIF('Кухненска_карта'!$A$2:$A$100,$A4,'Кухненска_карта'!$N$2:$N$100)>0,"Да","-") | P4: =IF(SUMIF('Кухненска_карта'!$A$2:$A$100,$A4,'Кухненска_карта'!$O$2:$O$100)>0,"Да","-") | Q4: =IF(SUMIF('Кухненска_карта'!$A$2:$A$100,$A4,'Кухненска_карта'!$P$2:$P$100)>0,"Да","-") | R4: =IF(SUMIF('Кухненска_карта'!$A$2:$A$100,$A4,'Кухненска_карта'!$Q$2:$Q$100)>0,"Да","-") | S4: =IF(SUMIF('Кухненска_карта'!$A$2:$A$100,$A4,'Кухненска_карта'!$R$2:$R$100)>0,"Да","-") | T4: =IF(SUMIF('Кухненска_карта'!$A$2:$A$100,$A4,'Кухненска_карта'!$S$2:$S$100)>0,"Да","-") | U4: =IF(SUMIF('Кухненска_карта'!$A$2:$A$100,$A4,'Кухненска_карта'!$T$2:$T$100)>0,"Да","-")
A5: Адана кебап | B5: Adana Kebab | C5: Основни | D5: Пикантни агнешко-телешки кебапчета на скара | E5: 4 | F5: =SUMIF('Кухненска_карта'!$A$2:$A$100,$A5,'Кухненска_карта'!$F$2:$F$100) | G5: =IF($E5=0,0,$F5/$E5) | H5: =IF(SUMIF('Кухненска_карта'!$A$2:$A$100,$A5,'Кухненска_карта'!$G$2:$G$100)>0,"Да","-") | I5: =IF(SUMIF('Кухненска_карта'!$A$2:$A$100,$A5,'Кухненска_карта'!$H$2:$H$100)>0,"Да","-") | J5: =IF(SUMIF('Кухненска_карта'!$A$2:$A$100,$A5,'Кухненска_карта'!$I$2:$I$100)>0,"Да","-") | K5: =IF(SUMIF('Кухненска_карта'!$A$2:$A$100,$A5,'Кухненска_карта'!$J$2:$J$100)>0,"Да","-") | L5: =IF(SUMIF('Кухненска_карта'!$A$2:$A$100,$A5,'Кухненска_карта'!$K$2:$K$100)>0,"Да","-") | M5: =IF(SUMIF('Кухненска_карта'!$A$2:$A$100,$A5,'Кухненска_карта'!$L$2:$L$100)>0,"Да","-") | N5: =IF(SUMIF('Кухненска_карта'!$A$2:$A$100,$A5,'Кухненска_карта'!$M$2:$M$100)>0,"Да","-") | O5: =IF(SUMIF('Кухненска_карта'!$A$2:$A$100,$A5,'Кухненска_карта'!$N$2:$N$100)>0,"Да","-") | P5: =IF(SUMIF('Кухненска_карта'!$A$2:$A$100,$A5,'Кухненска_карта'!$O$2:$O$100)>0,"Да","-") | Q5: =IF(SUMIF('Кухненска_карта'!$A$2:$A$100,$A5,'Кухненска_карта'!$P$2:$P$100)>0,"Да","-") | R5: =IF(SUMIF('Кухненска_карта'!$A$2:$A$100,$A5,'Кухненска_карта'!$Q$2:$Q$100)>0,"Да","-") | S5: =IF(SUMIF('Кухненска_карта'!$A$2:$A$100,$A5,'Кухненска_карта'!$R$2:$R$100)>0,"Да","-") | T5: =IF(SUMIF('Кухненска_карта'!$A$2:$A$100,$A5,'Кухненска_карта'!$S$2:$S$100)>0,"Да","-") | U5: =IF(SUMIF('Кухненска_карта'!$A$2:$A$100,$A5,'Кухненска_карта'!$T$2:$T$100)>0,"Да","-")
A6: Мантъ | B6: Turkish Mantı | C6: Основни | D6: Турски пелмени с кайма, поднесени с чеснов кисело мляко | E6: 6 | F6: =SUMIF('Кухненска_карта'!$A$2:$A$100,$A6,'Кухненска_карта'!$F$2:$F$100) | G6: =IF($E6=0,0,$F6/$E6) | H6: =IF(SUMIF('Кухненска_карта'!$A$2:$A$100,$A6,'Кухненска_карта'!$G$2:$G$100)>0,"Да","-") | I6: =IF(SUMIF('Кухненска_карта'!$A$2:$A$100,$A6,'Кухненска_карта'!$H$2:$H$100)>0,"Да","-") | J6: =IF(SUMIF('Кухненска_карта'!$A$2:$A$100,$A6,'Кухненска_карта'!$I$2:$I$100)>0,"Да","-") | K6: =IF(SUMIF('Кухненска_карта'!$A$2:$A$100,$A6,'Кухненска_карта'!$J$2:$J$100)>0,"Да","-") | L6: =IF(SUMIF('Кухненска_карта'!$A$2:$A$100,$A6,'Кухненска_карта'!$K$2:$K$100)>0,"Да","-") | M6: =IF(SUMIF('Кухненска_карта'!$A$2:$A$100,$A6,'Кухненска_карта'!$L$2:$L$100)>0,"Да","-") | N6: =IF(SUMIF('Кухненска_карта'!$A$2:$A$100,$A6,'Кухненска_карта'!$M$2:$M$100)>0,"Да","-") | O6: =IF(SUMIF('Кухненска_карта'!$A$2:$A$100,$A6,'Кухненска_карта'!$N$2:$N$100)>0,"Да","-") | P6: =IF(SUMIF('Кухненска_карта'!$A$2:$A$100,$A6,'Кухненска_карта'!$O$2:$O$100)>0,"Да","-") | Q6: =IF(SUMIF('Кухненска_карта'!$A$2:$A$100,$A6,'Кухненска_карта'!$P$2:$P$100)>0,"Да","-") | R6: =IF(SUMIF('Кухненска_карта'!$A$2:$A$100,$A6,'Кухненска_карта'!$Q$2:$Q$100)>0,"Да","-") | S6: =IF(SUMIF('Кухненска_карта'!$A$2:$A$100,$A6,'Кухненска_карта'!$R$2:$R$100)>0,"Да","-") | T6: =IF(SUMIF('Кухненска_карта'!$A$2:$A$100,$A6,'Кухненска_карта'!$S$2:$S$100)>0,"Да","-") | U6: =IF(SUMIF('Кухненска_карта'!$A$2:$A$100,$A6,'Кухненска_карта'!$T$2:$T$100)>0,"Да","-")
A7: Баклава | B7: Baklava | C7: Десерти | D7: Многолистно тесто с орехи, залято с ароматен сироп | E7: 12 | F7: =SUMIF('Кухненска_карта'!$A$2:$A$100,$A7,'Кухненска_карта'!$F$2:$F$100) | G7: =IF($E7=0,0,$F7/$E7) | H7: =IF(SUMIF('Кухненска_карта'!$A$2:$A$100,$A7,'Кухненска_карта'!$G$2:$G$100)>0,"Да","-") | I7: =IF(SUMIF('Кухненска_карта'!$A$2:$A$100,$A7,'Кухненска_карта'!$H$2:$H$100)>0,"Да","-") | J7: =IF(SUMIF('Кухненска_карта'!$A$2:$A$100,$A7,'Кухненска_карта'!$I$2:$I$100)>0,"Да","-") | K7: =IF(SUMIF('Кухненска_карта'!$A$2:$A$100,$A7,'Кухненска_карта'!$J$2:$J$100)>0,"Да","-") | L7: =IF(SUMIF('Кухненска_карта'!$A$2:$A$100,$A7,'Кухненска_карта'!$K$2:$K$100)>0,"Да","-") | M7: =IF(SUMIF('Кухненска_карта'!$A$2:$A$100,$A7,'Кухненска_карта'!$L$2:$L$100)>0,"Да","-") | N7: =IF(SUMIF('Кухненска_карта'!$A$2:$A$100,$A7,'Кухненска_карта'!$M$2:$M$100)>0,"Да","-") | O7: =IF(SUMIF('Кухненска_карта'!$A$2:$A$100,$A7,'Кухненска_карта'!$N$2:$N$100)>0,"Да","-") | P7: =IF(SUMIF('Кухненска_карта'!$A$2:$A$100,$A7,'Кухненска_карта'!$O$2:$O$100)>0,"Да","-") | Q7: =IF(SUMIF('Кухненска_карта'!$A$2:$A$100,$A7,'Кухненска_карта'!$P$2:$P$100)>0,"Да","-") | R7: =IF(SUMIF('Кухненска_карта'!$A$2:$A$100,$A7,'Кухненска_карта'!$Q$2:$Q$100)>0,"Да","-") | S7: =IF(SUMIF('Кухненска_карта'!$A$2:$A$100,$A7,'Кухненска_карта'!$R$2:$R$100)>0,"Да","-") | T7: =IF(SUMIF('Кухненска_карта'!$A$2:$A$100,$A7,'Кухненска_карта'!$S$2:$S$100)>0,"Да","-") | U7: =IF(SUMIF('Кухненска_карта'!$A$2:$A$100,$A7,'Кухненска_карта'!$T$2:$T$100)>0,"Да","-")
A8: Кюнефе | B8: Künefe | C8: Десерти | D8: Топъл десерт от кадаифено тесто и сирене в сироп | E8: 8 | F8: =SUMIF('Кухненска_карта'!$A$2:$A$100,$A8,'Кухненска_карта'!$F$2:$F$100) | G8: =IF($E8=0,0,$F8/$E8) | H8: =IF(SUMIF('Кухненска_карта'!$A$2:$A$100,$A8,'Кухненска_карта'!$G$2:$G$100)>0,"Да","-") | I8: =IF(SUMIF('Кухненска_карта'!$A$2:$A$100,$A8,'Кухненска_карта'!$H$2:$H$100)>0,"Да","-") | J8: =IF(SUMIF('Кухненска_карта'!$A$2:$A$100,$A8,'Кухненска_карта'!$I$2:$I$100)>0,"Да","-") | K8: =IF(SUMIF('Кухненска_карта'!$A$2:$A$100,$A8,'Кухненска_карта'!$J$2:$J$100)>0,"Да","-") | L8: =IF(SUMIF('Кухненска_карта'!$A$2:$A$100,$A8,'Кухненска_карта'!$K$2:$K$100)>0,"Да","-") | M8: =IF(SUMIF('Кухненска_карта'!$A$2:$A$100,$A8,'Кухненска_карта'!$L$2:$L$100)>0,"Да","-") | N8: =IF(SUMIF('Кухненска_карта'!$A$2:$A$100,$A8,'Кухненска_карта'!$M$2:$M$100)>0,"Да","-") | O8: =IF(SUMIF('Кухненска_карта'!$A$2:$A$100,$A8,'Кухненска_карта'!$N$2:$N$100)>0,"Да","-") | P8: =IF(SUMIF('Кухненска_карта'!$A$2:$A$100,$A8,'Кухненска_карта'!$O$2:$O$100)>0,"Да","-") | Q8: =IF(SUMIF('Кухненска_карта'!$A$2:$A$100,$A8,'Кухненска_карта'!$P$2:$P$100)>0,"Да","-") | R8: =IF(SUMIF('Кухненска_карта'!$A$2:$A$100,$A8,'Кухненска_карта'!$Q$2:$Q$100)>0,"Да","-") | S8: =IF(SUMIF('Кухненска_карта'!$A$2:$A$100,$A8,'Кухненска_карта'!$R$2:$R$100)>0,"Да","-") | T8: =IF(SUMIF('Кухненска_карта'!$A$2:$A$100,$A8,'Кухненска_карта'!$S$2:$S$100)>0,"Да","-") | U8: =IF(SUMIF('Кухненска_карта'!$A$2:$A$100,$A8,'Кухненска_карта'!$T$2:$T$100)>0,"Да","-")
A9: Турско кафе | B9: Turkish Coffee | C9: Напитки | D9: Сварено на пясък традиционно турско кафе | E9: 1 | F9: =SUMIF('Кухненска_карта'!$A$2:$A$100,$A9,'Кухненска_карта'!$F$2:$F$100) | G9: =IF($E9=0,0,$F9/$E9) | H9: =IF(SUMIF('Кухненска_карта'!$A$2:$A$100,$A9,'Кухненска_карта'!$G$2:$G$100)>0,"Да","-") | I9: =IF(SUMIF('Кухненска_карта'!$A$2:$A$100,$A9,'Кухненска_карта'!$H$2:$H$100)>0,"Да","-") | J9: =IF(SUMIF('Кухненска_карта'!$A$2:$A$100,$A9,'Кухненска_карта'!$I$2:$I$100)>0,"Да","-") | K9: =IF(SUMIF('Кухненска_карта'!$A$2:$A$100,$A9,'Кухненска_карта'!$J$2:$J$100)>0,"Да","-") | L9: =IF(SUMIF('Кухненска_карта'!$A$2:$A$100,$A9,'Кухненска_карта'!$K$2:$K$100)>0,"Да","-") | M9: =IF(SUMIF('Кухненска_карта'!$A$2:$A$100,$A9,'Кухненска_карта'!$L$2:$L$100)>0,"Да","-") | N9: =IF(SUMIF('Кухненска_карта'!$A$2:$A$100,$A9,'Кухненска_карта'!$M$2:$M$100)>0,"Да","-") | O9: =IF(SUMIF('Кухненска_карта'!$A$2:$A$100,$A9,'Кухненска_карта'!$N$2:$N$100)>0,"Да","-") | P9: =IF(SUMIF('Кухненска_карта'!$A$2:$A$100,$A9,'Кухненска_карта'!$O$2:$O$100)>0,"Да","-") | Q9: =IF(SUMIF('Кухненска_карта'!$A$2:$A$100,$A9,'Кухненска_карта'!$P$2:$P$100)>0,"Да","-") | R9: =IF(SUMIF('Кухненска_карта'!$A$2:$A$100,$A9,'Кухненска_карта'!$Q$2:$Q$100)>0,"Да","-") | S9: =IF(SUMIF('Кухненска_карта'!$A$2:$A$100,$A9,'Кухненска_карта'!$R$2:$R$100)>0,"Да","-") | T9: =IF(SUMIF('Кухненска_карта'!$A$2:$A$100,$A9,'Кухненска_карта'!$S$2:$S$100)>0,"Да","-") | U9: =IF(SUMIF('Кухненска_карта'!$A$2:$A$100,$A9,'Кухненска_карта'!$T$2:$T$100)>0,"Да","-")

Sheet Ценообразуване
A1: Целеви food cost %: | B1: 0.3 | C1: (жълто = въведи целевия % тук; всички редове по-долу го ползват)
A3: Рецепта | B3: Себестойност/порция (лв) | C3: Целеви food cost % | D3: Предложена цена (лв) | E3: Актуална цена в менюто (лв) | F3: Реален food cost % | G3: Марж (лв) | H3: Статус
A4: =INDEX('Рецепти'!$A:$A,2) | B4: =INDEX('Рецепти'!$G:$G,2) | C4: =$B$1 | D4: =IF($C4=0,0,$B4/$C4) | E4: 0 | F4: =IF($E4=0,0,$B4/$E4) | G4: =$E4-$B4 | H4: =IF($E4=0,"Въведи цена",IF($F4>$C4,"⚠ Над таргета","OK"))
A5: =INDEX('Рецепти'!$A:$A,3) | B5: =INDEX('Рецепти'!$G:$G,3) | C5: =$B$1 | D5: =IF($C5=0,0,$B5/$C5) | E5: 0 | F5: =IF($E5=0,0,$B5/$E5) | G5: =$E5-$B5 | H5: =IF($E5=0,"Въведи цена",IF($F5>$C5,"⚠ Над таргета","OK"))
A6: =INDEX('Рецепти'!$A:$A,4) | B6: =INDEX('Рецепти'!$G:$G,4) | C6: =$B$1 | D6: =IF($C6=0,0,$B6/$C6) | E6: 0 | F6: =IF($E6=0,0,$B6/$E6) | G6: =$E6-$B6 | H6: =IF($E6=0,"Въведи цена",IF($F6>$C6,"⚠ Над таргета","OK"))
A7: =INDEX('Рецепти'!$A:$A,5) | B7: =INDEX('Рецепти'!$G:$G,5) | C7: =$B$1 | D7: =IF($C7=0,0,$B7/$C7) | E7: 0 | F7: =IF($E7=0,0,$B7/$E7) | G7: =$E7-$B7 | H7: =IF($E7=0,"Въведи цена",IF($F7>$C7,"⚠ Над таргета","OK"))
A8: =INDEX('Рецепти'!$A:$A,6) | B8: =INDEX('Рецепти'!$G:$G,6) | C8: =$B$1 | D8: =IF($C8=0,0,$B8/$C8) | E8: 0 | F8: =IF($E8=0,0,$B8/$E8) | G8: =$E8-$B8 | H8: =IF($E8=0,"Въведи цена",IF($F8>$C8,"⚠ Над таргета","OK"))
A9: =INDEX('Рецепти'!$A:$A,7) | B9: =INDEX('Рецепти'!$G:$G,7) | C9: =$B$1 | D9: =IF($C9=0,0,$B9/$C9) | E9: 0 | F9: =IF($E9=0,0,$B9/$E9) | G9: =$E9-$B9 | H9: =IF($E9=0,"Въведи цена",IF($F9>$C9,"⚠ Над таргета","OK"))
A10: =INDEX('Рецепти'!$A:$A,8) | B10: =INDEX('Рецепти'!$G:$G,8) | C10: =$B$1 | D10: =IF($C10=0,0,$B10/$C10) | E10: 0 | F10: =IF($E10=0,0,$B10/$E10) | G10: =$E10-$B10 | H10: =IF($E10=0,"Въведи цена",IF($F10>$C10,"⚠ Над таргета","OK"))
A11: =INDEX('Рецепти'!$A:$A,9) | B11: =INDEX('Рецепти'!$G:$G,9) | C11: =$B$1 | D11: =IF($C11=0,0,$B11/$C11) | E11: 0 | F11: =IF($E11=0,0,$B11/$E11) | G11: =$E11-$B11 | H11: =IF($E11=0,"Въведи цена",IF($F11>$C11,"⚠ Над таргета","OK"))

Sheet Меню
A1: БЯЛА КЪЩА · Турска кухня
A3: ПРЕДЯСТИЯ
A4: =INDEX('Рецепти'!$A:$A,2)&" / "&INDEX('Рецепти'!$B:$B,2) | B4: =INDEX('Рецепти'!$D:$D,2) | D4: =INDEX('Ценообразуване'!$E:$E,4)
A5: =INDEX('Рецепти'!$A:$A,3)&" / "&INDEX('Рецепти'!$B:$B,3) | B5: =INDEX('Рецепти'!$D:$D,3) | D5: =INDEX('Ценообразуване'!$E:$E,5)
A7: ОСНОВНИ
A8: =INDEX('Рецепти'!$A:$A,4)&" / "&INDEX('Рецепти'!$B:$B,4) | B8: =INDEX('Рецепти'!$D:$D,4) | D8: =INDEX('Ценообразуване'!$E:$E,6)
A9: =INDEX('Рецепти'!$A:$A,5)&" / "&INDEX('Рецепти'!$B:$B,5) | B9: =INDEX('Рецепти'!$D:$D,5) | D9: =INDEX('Ценообразуване'!$E:$E,7)
A10: =INDEX('Рецепти'!$A:$A,6)&" / "&INDEX('Рецепти'!$B:$B,6) | B10: =INDEX('Рецепти'!$D:$D,6) | D10: =INDEX('Ценообразуване'!$E:$E,8)
A12: ДЕСЕРТИ
A13: =INDEX('Рецепти'!$A:$A,7)&" / "&INDEX('Рецепти'!$B:$B,7) | B13: =INDEX('Рецепти'!$D:$D,7) | D13: =INDEX('Ценообразуване'!$E:$E,9)
A14: =INDEX('Рецепти'!$A:$A,8)&" / "&INDEX('Рецепти'!$B:$B,8) | B14: =INDEX('Рецепти'!$D:$D,8) | D14: =INDEX('Ценообразуване'!$E:$E,10)
A16: НАПИТКИ
A17: =INDEX('Рецепти'!$A:$A,9)&" / "&INDEX('Рецепти'!$B:$B,9) | B17: =INDEX('Рецепти'!$D:$D,9) | D17: =INDEX('Ценообразуване'!$E:$E,11)
